Workbook

Sheet Read me
B2: Furniture landed-cost scenario model
B4: What this answers
B5: If a mid-size US furniture importer moves volume out of China, what happens to its total landed cost once duty, freight and fees are counted - and how much more can a new factory charge before the move stops saving money?
B7: What is real and what is assumed
B8: REAL: duty rates. 'Duty rates' holds the effective rate US importers actually paid (calculated duty / customs value) by origin and product line, Jun 2026-Aug 2026, from the US Census Bureau international trade API.
B9: ASSUMED: the company. Purchase volumes, today's sourcing mix, freight costs and factory prices are illustrative inputs for a $40M-a-year importer. Replace them with real numbers before using this for a decision.
B11: How to use it
B12: 1. Inputs - change purchase volumes, factory prices, freight, and override any duty rate.
B13: 2. Scenarios - edit today's mix. Scenarios 2-4 move today's China volume elsewhere and update on their own; type over them to define a different scenario.
B14: 3. Results - landed cost for each scenario and the change against today.
B15: 4. Break-even - the highest factory price premium over China at which each origin is still cheaper landed.
B17: Cell colours
... B26: - Merchandise processing fee (0.3464%) and harbor maintenance fee (0.125%) are applied as flat percentages; the per-entry MPF minimum and maximum are ignored.

Sheet Inputs
B1: Inputs
B2: Yellow cells are assumptions for an illustrative importer - replace with real figures.
B4: 1. What the company buys each year
B5: HS6 | C5: Product line | D5: Purchases at China FOB prices ($)
B6: 940161 | C6: Upholstered wood-frame seating | D6: 12000000
B7: 940350 | C7: Wooden bedroom furniture | D7: 8000000
B8: 940360 | C8: Other wooden furniture | D8: 7000000
B9: 940340 | C9: Kitchen cabinets and vanities | D9: 5000000
B10: 940171 | C10: Upholstered metal-frame seating | D10: 4000000
B11: 940320 | C11: Other metal furniture | D11: 4000000
C12: Total | D12: =SUM(D6:D11) -> 40000000
B14: 2. Cost assumptions by origin
C15: Assumption | D15: China | E15: Vietnam | F15: Malaysia | G15: Indonesia | H15: Cambodia | I15: Mexico
C16: Factory price vs China (1.00 = same price) | D16: 1 | E16: 1 | F16: 1 | G16: 1 | H16: 1 | I16: 1
C17: Freight and insurance (% of FOB) | D17: 0.07 | E17: 0.075 | F17: 0.075 | G17: 0.08 | H17: 0.08 | I17: 0.035
C18: Merchandise processing fee applies (1 = yes) | D18: 1 | E18: 1 | F18: 1 | G18: 1 | H18: 1 | I18: 0
C19: Harbor maintenance fee applies (1 = yes) | D19: 1 | E19: 1 | F19: 1 | G19: 1 | H19: 1 | I19: 0
B21: 3. Fee rates
C22: Merchandise processing fee (% of value) | D22: 0.003464
C23: Harbor maintenance fee (% of value) | D23: 0.00125
C24: Fee rate applied, by origin | D24: =$D$22*D18+$D$23*D19 -> 0.004714 | E24: =$D$22*E18+$D$23*E19 -> 0.004714 | F24: =$D$22*F18+$D$23*F19 -> 0.004714 | G24: =$D$22*G18+$D$23*G19 -> 0.004714 | H24: =$D$22*H18+$D$23*H19 -> 0.004714 | I24: =$D$22*I18+$D$23*I19 -> 0
B26: 4. Duty rate overrides (leave blank to use the observed rate)
B27: HS6 | C27: Product line | D27: China | E27: Vietnam | F27: Malaysia | G27: Indonesia | H27: Cambodia | I27: Mexico
B28: 940161 | C28: Upholstered wood-frame seating
B29: 940350 | C29: Wooden bedroom furniture
B30: 940360 | C30: Other wooden furniture
B31: 940340 | C31: Kitchen cabinets and vanities
B32: 940171 | C32: Upholstered metal-frame seating
B33: 940320 | C33: Other metal furniture
B35: 5. Duty rate used in the model
B36: HS6 | C36: Product line | D36: China | E36: Vietnam | F36: Malaysia | G36: Indonesia | H36: Cambodia | I36: Mexico
B37: 940161 | C37: Upholstered wood-frame seating | D37: =IF(D28="",'Duty rates'!D6,D28) -> 0.39330567 | E37: =IF(E28="",'Duty rates'!E6,E28) -> 0.24801316 | F37: =IF(F28="",'Duty rates'!F6,F28) -> 0.25374277 | G37: =IF(G28="",'Duty rates'!G6,G28) -> 0.23065041 | H37: =IF(H28="",'Duty rates'!H6,H28) -> 0.25159829 | I37: =IF(I28="",'Duty rates'!I6,I28) -> 0.24476363
B38: 940350 | C38: Wooden bedroom furniture | D38: =IF(D29="",'Duty rates'!D7,D29) -> 0.35496596 | E38: =IF(E29="",'Duty rates'!E7,E29) -> 0.10565416 | F38: =IF(F29="",'Duty rates'!F7,F29) -> 0.095269622 | G38: =IF(G29="",'Duty rates'!G7,G29) -> 0.097231466 | H38: =IF(H29="",'Duty rates'!H7,H29) -> 0.092367752 | I38: =IF(I29="",'Duty rates'!I7,I29) -> 0.00012161558
B39: 940360 | C39: Other wooden furniture | D39: =IF(D30="",'Duty rates'!D8,D30) -> 0.35788779 | E39: =IF(E30="",'Duty rates'!E8,E30) -> 0.1330744 | F39: =IF(F30="",'Duty rates'!F8,F30) -> 0.10334735 | G39: =IF(G30="",'Duty rates'!G8,G30) -> 0.10065494 | H39: =IF(H30="",'Duty rates'!H8,H30) -> 0.13457674 | I39: =IF(I30="",'Duty rates'!I8,I30) -> 0.088078125
B40: 940340 | C40: Kitchen cabinets and vanities | D40: =IF(D31="",'Duty rates'!D9,D31) -> 0.37895995 | E40: =IF(E31="",'Duty rates'!E9,E31) -> 0.22870174 | F40: =IF(F31="",'Duty rates'!F9,F31) -> 0.23845345 | G40: =IF(G31="",'Duty rates'!G9,G31) -> 0.23570735 | H40: =IF(H31="",'Duty rates'!H9,H31) -> 0.24740863 | I40: =IF(I31="",'Duty rates'!I9,I31) -> 0.22244998
B41: 940171 | C41: Upholstered metal-frame seating | D41: =IF(D32="",'Duty rates'!D10,D32) -> 0.19629297 | E41: =IF(E32="",'Duty rates'!E10,E32) -> 0.10230773 | F41: =IF(F32="",'Duty rates'!F10,F32) -> 0.13592827 | G41: =IF(G32="",'Duty rates'!G10,G32) -> 0.091870682 | H41: =IF(H32="",'Duty rates'!H10,H32) -> 0.090298581 | I41: =IF(I32="",'Duty rates'!I10,I32) -> 0.0043303298
B42: 940320 | C42: Other metal furniture | D42: =IF(D33="",'Duty rates'!D11,D33) -> 0.36629034 | E42: =IF(E33="",'Duty rates'!E11,E33) -> 0.11548319 | F42: =IF(F33="",'Duty rates'!F11,F33) -> 0.10653058 | G42: =IF(G33="",'Duty rates'!G11,G33) -> 0.096552585 | H42: =IF(H33="",'Duty rates'!H11,H33) -> 0.10062035 | I42: =IF(I33="",'Duty rates'!I11,I33) -> 0.046166177

Sheet Scenarios
B1: Sourcing scenarios
B2: Share of each product line bought from each origin. Scenarios 2-4 move today's China share elsewhere - type over them to build your own.
B4: Scenario 1 | C4: Today's sourcing
B5: HS6 | C5: Product line | D5: China | E5: Vietnam | F5: Malaysia | G5: Indonesia | H5: Cambodia | I5: Mexico | J5: Total | K5: Check
B6: 940161 | C6: Upholstered wood-frame seating | D6: 0.45 | E6: 0.4 | F6: 0.1 | G6: 0.05 | H6: 0 | I6: 0 | J6: =SUM(D6:I6) -> 1 | K6: =IF(ABS(J6-1)>0.0001,"Mix must add to 100%","OK") -> OK
B7: 940350 | C7: Wooden bedroom furniture | D7: 0.3 | E7: 0.55 | F7: 0.1 | G7: 0.05 | H7: 0 | I7: 0 | J7: =SUM(D7:I7) -> 1 | K7: =IF(ABS(J7-1)>0.0001,"Mix must add to 100%","OK") -> OK
B8: 940360 | C8: Other wooden furniture | D8: 0.4 | E8: 0.45 | F8: 0.1 | G8: 0.05 | H8: 0 | I8: 0 | J8: =SUM(D8:I8) -> 1 | K8: =IF(ABS(J8-1)>0.0001,"Mix must add to 100%","OK") -> OK
B9: 940340 | C9: Kitchen cabinets and vanities | D9: 0.5 | E9: 0.4 | F9: 0.1 | G9: 0 | H9: 0 | I9: 0 | J9: =SUM(D9:I9) -> 1 | K9: =IF(ABS(J9-1)>0.0001,"Mix must add to 100%","OK") -> OK
B10: 940171 | C10: Upholstered metal-frame seating | D10: 0.65 | E10: 0.35 | F10: 0 | G10: 0 | H10: 0 | I10: 0 | J10: =SUM(D10:I10) -> 1 | K10: =IF(ABS(J10-1)>0.0001,"Mix must add to 100%","OK") -> OK
B11: 940320 | C11: Other metal furniture | D11: 0.7 | E11: 0.25 | F11: 0 | G11: 0 | H11: 0 | I11: 0.05 | J11: =SUM(D11:I11) -> 1 | K11: =IF(ABS(J11-1)>0.0001,"Mix must add to 100%","OK") -> OK
B15: Scenario 2 | C15: Move China volume to Vietnam
B16: HS6 | C16: Product line | D16: China | E16: Vietnam | F16: Malaysia | G16: Indonesia | H16: Cambodia | I16: Mexico | J16: Total | K16: Check
B17: 940161 | C17: Upholstered wood-frame seating | D17: 0 | E17: =E6+1*$D6 -> 0.85 | F17: =F6 -> 0.1 | G17: =G6 -> 0.05 | H17: =H6 -> 0 | I17: =I6 -> 0 | J17: =SUM(D17:I17) -> 1 | K17: =IF(ABS(J17-1)>0.0001,"Mix must add to 100%","OK") -> OK
B18: 940350 | C18: Wooden bedroom furniture | D18: 0 | E18: =E7+1*$D7 -> 0.85 | F18: =F7 -> 0.1 | G18: =G7 -> 0.05 | H18: =H7 -> 0 | I18: =I7 -> 0 | J18: =SUM(D18:I18) -> 1 | K18: =IF(ABS(J18-1)>0.0001,"Mix must add to 100%","OK") -> OK
B19: 940360 | C19: Other wooden furniture | D19: 0 | E19: =E8+1*$D8 -> 0.85 | F19: =F8 -> 0.1 | G19: =G8 -> 0.05 | H19: =H8 -> 0 | I19: =I8 -> 0 | J19: =SUM(D19:I19) -> 1 | K19: =IF(ABS(J19-1)>0.0001,"Mix must add to 100%","OK") -> OK
B20: 940340 | C20: Kitchen cabinets and vanities | D20: 0 | E20: =E9+1*$D9 -> 0.9 | F20: =F9 -> 0.1 | G20: =G9 -> 0 | H20: =H9 -> 0 | I20: =I9 -> 0 | J20: =SUM(D20:I20) -> 1 | K20: =IF(ABS(J20-1)>0.0001,"Mix must add to 100%","OK") -> OK
B21: 940171 | C21: Upholstered metal-frame seating | D21: 0 | E21: =E10+1*$D10 -> 1 | F21: =F10 -> 0 | G21: =G10 -> 0 | H21: =H10 -> 0 | I21: =I10 -> 0 | J21: =SUM(D21:I21) -> 1 | K21: =IF(ABS(J21-1)>0.0001,"Mix must add to 100%","OK") -> OK
B22: 940320 | C22: Other metal furniture | D22: 0 | E22: =E11+1*$D11 -> 0.95 | F22: =F11 -> 0 | G22: =G11 -> 0 | H22: =H11 -> 0 | I22: =I11 -> 0.05 | J22: =SUM(D22:I22) -> 1 | K22: =IF(ABS(J22-1)>0.0001,"Mix must add to 100%","OK") -> OK
B26: Scenario 3 | C26: Spread China volume: Vietnam / Cambodia / Indonesia
B27: HS6 | C27: Product line | D27: China | E27: Vietnam | F27: Malaysia | G27: Indonesia | H27: Cambodia | I27: Mexico | J27: Total | K27: Check
B28: 940161 | C28: Upholstered wood-frame seating | D28: 0 | E28: =E6+0.4*$D6 -> 0.58 | F28: =F6 -> 0.1 | G28: =G6+0.3*$D6 -> 0.185 | H28: =H6+0.3*$D6 -> 0.135 | I28: =I6 -> 0 | J28: =SUM(D28:I28) -> 1 | K28: =IF(ABS(J28-1)>0.0001,"Mix must add to 100%","OK") -> OK
B29: 940350 | C29: Wooden bedroom furniture | D29: 0 | E29: =E7+0.4*$D7 -> 0.67 | F29: =F7 -> 0.1 | G29: =G7+0.3*$D7 -> 0.14 | H29: =H7+0.3*$D7 -> 0.09 | I29: =I7 -> 0 | J29: =SUM(D29:I29) -> 1 | K29: =IF(ABS(J29-1)>0.0001,"Mix must add to 100%","OK") -> OK
B30: 940360 | C30: Other wooden furniture | D30: 0 | E30: =E8+0.4*$D8 -> 0.61 | F30: =F8 -> 0.1 | G30: =G8+0.3*$D8 -> 0.17 | H30: =H8+0.3*$D8 -> 0.12 | I30: =I8 -> 0 | J30: =SUM(D30:I30) -> 1 | K30: =IF(ABS(J30-1)>0.0001,"Mix must add to 100%","OK") -> OK
B31: 940340 | C31: Kitchen cabinets and vanities | D31: 0 | E31: =E9+0.4*$D9 -> 0.6 | F31: =F9 -> 0.1 | G31: =G9+0.3*$D9 -> 0.15 | H31: =H9+0.3*$D9 -> 0.15 | I31: =I9 -> 0 | J31: =SUM(D31:I31) -> 1 | K31: =IF(ABS(J31-1)>0.0001,"Mix must add to 100%","OK") -> OK
B32: 940171 | C32: Upholstered metal-frame seating | D32: 0 | E32: =E10+0.4*$D10 -> 0.61 | F32: =F10 -> 0 | G32: =G10+0.3*$D10 -> 0.195 | H32: =H10+0.3*$D10 -> 0.195 | I32: =I10 -> 0 | J32: =SUM(D32:I32) -> 1 | K32: =IF(ABS(J32-1)>0.0001,"Mix must add to 100%","OK") -> OK
B33: 940320 | C33: Other metal furniture | D33: 0 | E33: =E11+0.4*$D11 -> 0.53 | F33: =F11 -> 0 | G33: =G11+0.3*$D11 -> 0.21 | H33: =H11+0.3*$D11 -> 0.21 | I33: =I11 -> 0.05 | J33: =SUM(D33:I33) -> 1 | K33: =IF(ABS(J33-1)>0.0001,"Mix must add to 100%","OK") -> OK
B37: Scenario 4 | C37: Nearshore China volume to Mexico
B38: HS6 | C38: Product line | D38: China | E38: Vietnam | F38: Malaysia | G38: Indonesia | H38: Cambodia | I38: Mexico | J38: Total | K38: Check
B39: 940161 | C39: Upholstered wood-frame seating | D39: 0 | E39: =E6 -> 0.4 | F39: =F6 -> 0.1 | G39: =G6 -> 0.05 | H39: =H6 -> 0 | I39: =I6+1*$D6 -> 0.45 | J39: =SUM(D39:I39) -> 1 | K39: =IF(ABS(J39-1)>0.0001,"Mix must add to 100%","OK") -> OK
B40: 940350 | C40: Wooden bedroom furniture | D40: 0 | E40: =E7 -> 0.55 | F40: =F7 -> 0.1 | G40: =G7 -> 0.05 | H40: =H7 -> 0 | I40: =I7+1*$D7 -> 0.3 | J40: =SUM(D40:I40) -> 1 | K40: =IF(ABS(J40-1)>0.0001,"Mix must add to 100%","OK") -> OK
B41: 940360 | C41: Other wooden furniture | D41: 0 | E41: =E8 -> 0.45 | F41: =F8 -> 0.1 | G41: =G8 -> 0.05 | H41: =H8 -> 0 | I41: =I8+1*$D8 -> 0.4 | J41: =SUM(D41:I41) -> 1 | K41: =IF(ABS(J41-1)>0.0001,"Mix must add to 100%","OK") -> OK
B42: 940340 | C42: Kitchen cabinets and vanities | D42: 0 | E42: =E9 -> 0.4 | F42: =F9 -> 0.1 | G42: =G9 -> 0 | H42: =H9 -> 0 | I42: =I9+1*$D9 -> 0.5 | J42: =SUM(D42:I42) -> 1 | K42: =IF(ABS(J42-1)>0.0001,"Mix must add to 100%","OK") -> OK
B43: 940171 | C43: Upholstered metal-frame seating | D43: 0 | E43: =E10 -> 0.35 | F43: =F10 -> 0 | G43: =G10 -> 0 | H43: =H10 -> 0 | I43: =I10+1*$D10 -> 0.65 | J43: =SUM(D43:I43) -> 1 | K43: =IF(ABS(J43-1)>0.0001,"Mix must add to 100%","OK") -> OK
B44: 940320 | C44: Other metal furniture | D44: 0 | E44: =E11 -> 0.25 | F44: =F11 -> 0 | G44: =G11 -> 0 | H44: =H11 -> 0 | I44: =I11+1*$D11 -> 0.75 | J44: =SUM(D44:I44) -> 1 | K44: =IF(ABS(J44-1)>0.0001,"Mix must add to 100%","OK") -> OK

Sheet Results
B1: Landed cost by scenario
B2: Landed cost = factory price + freight + duty + customs fees. Annual, US$.
B4: Summary
B5: # | C5: Scenario | D5: Landed cost ($) | E5: vs today ($) | F5: vs today (%) | G5: Duty paid ($) | H5: Effective duty rate | I5: FOB cost ($)
B6: 1 | C6: =Scenarios!C4 -> Today's sourcing | D6: =H22 -> 53139762 | E6: =D6-$D$6 -> 0 | F6: =IF($D$6=0,0,D6/$D$6-1) -> 0 | G6: =F22 -> 10045895 | H6: =IF(D22=0,0,F22/D22) -> 0.25114737 | I6: =D22 -> 40000000
B7: 2 | C7: =Scenarios!C15 -> Move China volume to Vietnam | D7: =H32 -> 49897590 | E7: =D7-$D$6 -> -3242172.5 | F7: =IF($D$6=0,0,D7/$D$6-1) -> -0.061012176 | G7: =F32 -> 6711222.3 | H7: =IF(D32=0,0,F32/D32) -> 0.16778056 | I7: =D32 -> 40000000
B8: 3 | C8: =Scenarios!C26 -> Spread China volume: Vietnam / Cambodia / Indonesia | D8: =H42 -> 49862559 | E8: =D8-$D$6 -> -3277203.4 | F8: =IF($D$6=0,0,D8/$D$6-1) -> -0.061671397 | G8: =F42 -> 6620691.5 | H8: =IF(D42=0,0,F42/D42) -> 0.16551729 | I8: =D42 -> 40000000
B9: 4 | C9: =Scenarios!C37 -> Nearshore China volume to Mexico | D9: =H52 -> 48209107 | E9: =D9-$D$6 -> -4930655 | F9: =IF($D$6=0,0,D9/$D$6-1) -> -0.092786546 | G9: =F52 -> 5849948.9 | H9: =IF(D52=0,0,F52/D52) -> 0.14624872 | I9: =D52 -> 40000000
C11: Negative 'vs today' = the scenario is cheaper than today's sourcing.
B14: Scenario 1 | C14: =Scenarios!C4 -> Today's sourcing
B15: HS6 | C15: Product line | D15: FOB cost ($) | E15: Freight ($) | F15: Duty ($) | G15: Fees ($) | H15: Landed cost ($) | I15: Duty rate
B16: 940161 | C16: Upholstered wood-frame seating | D16: =Inputs!$D$6*SUMPRODUCT(Scenarios!$D$6:$I$6,Inputs!$D$16:$I$16) -> 12000000 | E16: =Inputs!$D$6*SUMPRODUCT(Scenarios!$D$6:$I$6,Inputs!$D$16:$I$16,Inputs!$D$17:$I$17) -> 876000 | F16: =Inputs!$D$6*SUMPRODUCT(Scenarios!$D$6:$I$6,Inputs!$D$16:$I$16,Inputs!$D$37:$I$37) -> 3757195.4 | G16: =Inputs!$D$6*SUMPRODUCT(Scenarios!$D$6:$I$6,Inputs!$D$16:$I$16,Inputs!$D$24:$I$24) -> 56568 | H16: =SUM(D16:G16) -> 16689763 | I16: =IF(D16=0,0,F16/D16) -> 0.31309961
B17: 940350 | C17: Wooden bedroom furniture | D17: =Inputs!$D$7*SUMPRODUCT(Scenarios!$D$7:$I$7,Inputs!$D$16:$I$16) -> 8000000 | E17: =Inputs!$D$7*SUMPRODUCT(Scenarios!$D$7:$I$7,Inputs!$D$16:$I$16,Inputs!$D$17:$I$17) -> 590000 | F17: =Inputs!$D$7*SUMPRODUCT(Scenarios!$D$7:$I$7,Inputs!$D$16:$I$16,Inputs!$D$38:$I$38) -> 1431904.9 | G17: =Inputs!$D$7*SUMPRODUCT(Scenarios!$D$7:$I$7,Inputs!$D$16:$I$16,Inputs!$D$24:$I$24) -> 37712 | H17: =SUM(D17:G17) -> 10059617 | I17: =IF(D17=0,0,F17/D17) -> 0.17898811
B18: 940360 | C18: Other wooden furniture | D18: =Inputs!$D$8*SUMPRODUCT(Scenarios!$D$8:$I$8,Inputs!$D$16:$I$16) -> 7000000 | E18: =Inputs!$D$8*SUMPRODUCT(Scenarios!$D$8:$I$8,Inputs!$D$16:$I$16,Inputs!$D$17:$I$17) -> 512750 | F18: =Inputs!$D$8*SUMPRODUCT(Scenarios!$D$8:$I$8,Inputs!$D$16:$I$16,Inputs!$D$39:$I$39) -> 1528842.5 | G18: =Inputs!$D$8*SUMPRODUCT(Scenarios!$D$8:$I$8,Inputs!$D$16:$I$16,Inputs!$D$24:$I$24) -> 32998 | H18: =SUM(D18:G18) -> 9074590.5 | I18: =IF(D18=0,0,F18/D18) -> 0.21840608
B19: 940340 | C19: Kitchen cabinets and vanities | D19: =Inputs!$D$9*SUMPRODUCT(Scenarios!$D$9:$I$9,Inputs!$D$16:$I$16) -> 5000000 | E19: =Inputs!$D$9*SUMPRODUCT(Scenarios!$D$9:$I$9,Inputs!$D$16:$I$16,Inputs!$D$17:$I$17) -> 362500 | F19: =Inputs!$D$9*SUMPRODUCT(Scenarios!$D$9:$I$9,Inputs!$D$16:$I$16,Inputs!$D$40:$I$40) -> 1524030.1 | G19: =Inputs!$D$9*SUMPRODUCT(Scenarios!$D$9:$I$9,Inputs!$D$16:$I$16,Inputs!$D$24:$I$24) -> 23570 | H19: =SUM(D19:G19) -> 6910100.1 | I19: =IF(D19=0,0,F19/D19) -> 0.30480601
B20: 940171 | C20: Upholstered metal-frame seating | D20: =Inputs!$D$10*SUMPRODUCT(Scenarios!$D$10:$I$10,Inputs!$D$16:$I$16) -> 4000000 | E20: =Inputs!$D$10*SUMPRODUCT(Scenarios!$D$10:$I$10,Inputs!$D$16:$I$16,Inputs!$D$17:$I$17) -> 287000 | F20: =Inputs!$D$10*SUMPRODUCT(Scenarios!$D$10:$I$10,Inputs!$D$16:$I$16,Inputs!$D$41:$I$41) -> 653592.56 | G20: =Inputs!$D$10*SUMPRODUCT(Scenarios!$D$10:$I$10,Inputs!$D$16:$I$16,Inputs!$D$24:$I$24) -> 18856 | H20: =SUM(D20:G20) -> 4959448.6 | I20: =IF(D20=0,0,F20/D20) -> 0.16339814
B21: 940320 | C21: Other metal furniture | D21: =Inputs!$D$11*SUMPRODUCT(Scenarios!$D$11:$I$11,Inputs!$D$16:$I$16) -> 4000000 | E21: =Inputs!$D$11*SUMPRODUCT(Scenarios!$D$11:$I$11,Inputs!$D$16:$I$16,Inputs!$D$17:$I$17) -> 278000 | F21: =Inputs!$D$11*SUMPRODUCT(Scenarios!$D$11:$I$11,Inputs!$D$16:$I$16,Inputs!$D$42:$I$42) -> 1150329.4 | G21: =Inputs!$D$11*SUMPRODUCT(Scenarios!$D$11:$I$11,Inputs!$D$16:$I$16,Inputs!$D$24:$I$24) -> 17913.2 | H21: =SUM(D21:G21) -> 5446242.6 | I21: =IF(D21=0,0,F21/D21) -> 0.28758235
C22: Total | D22: =SUM(D16:D21) -> 40000000 | E22: =SUM(E16:E21) -> 2906250 | F22: =SUM(F16:F21) -> 10045895 | G22: =SUM(G16:G21) -> 187617.2 | H22: =SUM(H16:H21) -> 53139762 | I22: =IF(D22=0,0,F22/D22) -> 0.25114737
B24: Scenario 2 | C24: =Scenarios!C15 -> Move China volume to Vietnam
B25: HS6 | C25: Product line | D25: FOB cost ($) | E25: Freight ($) | F25: Duty ($) | G25: Fees ($) | H25: Landed cost ($) | I25: Duty rate
B26: 940161 | C26: Upholstered wood-frame seating | D26: =Inputs!$D$6*SUMPRODUCT(Scenarios!$D$17:$I$17,Inputs!$D$16:$I$16) -> 12000000 | E26: =Inputs!$D$6*SUMPRODUCT(Scenarios!$D$17:$I$17,Inputs!$D$16:$I$16,Inputs!$D$17:$I$17) -> 903000 | F26: =Inputs!$D$6*SUMPRODUCT(Scenarios!$D$17:$I$17,Inputs!$D$16:$I$16,Inputs!$D$37:$I$37) -> 2972615.8 | G26: =Inputs!$D$6*SUMPRODUCT(Scenarios!$D$17:$I$17,Inputs!$D$16:$I$16,Inputs!$D$24:$I$24) -> 56568 | H26: =SUM(D26:G26) -> 15932184 | I26: =IF(D26=0,0,F26/D26) -> 0.24771798
B27: 940350 | C27: Wooden bedroom furniture | D27: =Inputs!$D$7*SUMPRODUCT(Scenarios!$D$18:$I$18,Inputs!$D$16:$I$16) -> 8000000 | E27: =Inputs!$D$7*SUMPRODUCT(Scenarios!$D$18:$I$18,Inputs!$D$16:$I$16,Inputs!$D$17:$I$17) -> 602000 | F27: =Inputs!$D$7*SUMPRODUCT(Scenarios!$D$18:$I$18,Inputs!$D$16:$I$16,Inputs!$D$38:$I$38) -> 833556.59 | G27: =Inputs!$D$7*SUMPRODUCT(Scenarios!$D$18:$I$18,Inputs!$D$16:$I$16,Inputs!$D$24:$I$24) -> 37712 | H27: =SUM(D27:G27) -> 9473268.6 | I27: =IF(D27=0,0,F27/D27) -> 0.10419457
B28: 940360 | C28: Other wooden furniture | D28: =Inputs!$D$8*SUMPRODUCT(Scenarios!$D$19:$I$19,Inputs!$D$16:$I$16) -> 7000000 | E28: =Inputs!$D$8*SUMPRODUCT(Scenarios!$D$19:$I$19,Inputs!$D$16:$I$16,Inputs!$D$17:$I$17) -> 526750 | F28: =Inputs!$D$8*SUMPRODUCT(Scenarios!$D$19:$I$19,Inputs!$D$16:$I$16,Inputs!$D$39:$I$39) -> 899365.05 | G28: =Inputs!$D$8*SUMPRODUCT(Scenarios!$D$19:$I$19,Inputs!$D$16:$I$16,Inputs!$D$24:$I$24) -> 32998 | H28: =SUM(D28:G28) -> 8459113.1 | I28: =IF(D28=0,0,F28/D28) -> 0.12848072
B29: 940340 | C29: Kitchen cabinets and vanities | D29: =Inputs!$D$9*SUMPRODUCT(Scenarios!$D$20:$I$20,Inputs!$D$16:$I$16) -> 5000000 | E29: =Inputs!$D$9*SUMPRODUCT(Scenarios!$D$20:$I$20,Inputs!$D$16:$I$16,Inputs!$D$17:$I$17) -> 375000 | F29: =Inputs!$D$9*SUMPRODUCT(Scenarios!$D$20:$I$20,Inputs!$D$16:$I$16,Inputs!$D$40:$I$40) -> 1148384.6 | G29: =Inputs!$D$9*SUMPRODUCT(Scenarios!$D$20:$I$20,Inputs!$D$16:$I$16,Inputs!$D$24:$I$24) -> 23570 | H29: =SUM(D29:G29) -> 6546954.6 | I29: =IF(D29=0,0,F29/D29) -> 0.22967691
B30: 940171 | C30: Upholstered metal-frame seating | D30: =Inputs!$D$10*SUMPRODUCT(Scenarios!$D$21:$I$21,Inputs!$D$16:$I$16) -> 4000000 | E30: =Inputs!$D$10*SUMPRODUCT(Scenarios!$D$21:$I$21,Inputs!$D$16:$I$16,Inputs!$D$17:$I$17) -> 300000 | F30: =Inputs!$D$10*SUMPRODUCT(Scenarios!$D$21:$I$21,Inputs!$D$16:$I$16,Inputs!$D$41:$I$41) -> 409230.93 | G30: =Inputs!$D$10*SUMPRODUCT(Scenarios!$D$21:$I$21,Inputs!$D$16:$I$16,Inputs!$D$24:$I$24) -> 18856 | H30: =SUM(D30:G30) -> 4728086.9 | I30: =IF(D30=0,0,F30/D30) -> 0.10230773
B31: 940320 | C31: Other metal furniture | D31: =Inputs!$D$11*SUMPRODUCT(Scenarios!$D$22:$I$22,Inputs!$D$16:$I$16) -> 4000000 | E31: =Inputs!$D$11*SUMPRODUCT(Scenarios!$D$22:$I$22,Inputs!$D$16:$I$16,Inputs!$D$17:$I$17) -> 292000 | F31: =Inputs!$D$11*SUMPRODUCT(Scenarios!$D$22:$I$22,Inputs!$D$16:$I$16,Inputs!$D$42:$I$42) -> 448069.35 | G31: =Inputs!$D$11*SUMPRODUCT(Scenarios!$D$22:$I$22,Inputs!$D$16:$I$16,Inputs!$D$24:$I$24) -> 17913.2 | H31: =SUM(D31:G31) -> 4757982.6 | I31: =IF(D31=0,0,F31/D31) -> 0.11201734
C32: Total | D32: =SUM(D26:D31) -> 40000000 | E32: =SUM(E26:E31) -> 2998750 | F32: =SUM(F26:F31) -> 6711222.3 | G32: =SUM(G26:G31) -> 187617.2 | H32: =SUM(H26:H31) -> 49897590 | I32: =IF(D32=0,0,F32/D32) -> 0.16778056
B34: Scenario 3 | C34: =Scenarios!C26 -> Spread China volume: Vietnam / Cambodia / Indonesia
B35: HS6 | C35: Product line | D35: FOB cost ($) | E35: Freight ($) | F35: Duty ($) | G35: Fees ($) | H35: Landed cost ($) | I35: Duty rate
B36: 940161 | C36: Upholstered wood-frame seating | D36: =Inputs!$D$6*SUMPRODUCT(Scenarios!$D$28:$I$28,Inputs!$D$16:$I$16) -> 12000000 | E36: =Inputs!$D$6*SUMPRODUCT(Scenarios!$D$28:$I$28,Inputs!$D$16:$I$16,Inputs!$D$17:$I$17) -> 919200 | F36: =Inputs!$D$6*SUMPRODUCT(Scenarios!$D$28:$I$28,Inputs!$D$16:$I$16,Inputs!$D$37:$I$37) -> 2950296.1 | G36: =Inputs!$D$6*SUMPRODUCT(Scenarios!$D$28:$I$28,Inputs!$D$16:$I$16,Inputs!$D$24:$I$24) -> 56568 | H36: =SUM(D36:G36) -> 15926064 | I36: =IF(D36=0,0,F36/D36) -> 0.24585801
B37: 940350 | C37: Wooden bedroom furniture | D37: =Inputs!$D$7*SUMPRODUCT(Scenarios!$D$29:$I$29,Inputs!$D$16:$I$16) -> 8000000 | E37: =Inputs!$D$7*SUMPRODUCT(Scenarios!$D$29:$I$29,Inputs!$D$16:$I$16,Inputs!$D$17:$I$17) -> 609200 | F37: =Inputs!$D$7*SUMPRODUCT(Scenarios!$D$29:$I$29,Inputs!$D$16:$I$16,Inputs!$D$38:$I$38) -> 817926.04 | G37: =Inputs!$D$7*SUMPRODUCT(Scenarios!$D$29:$I$29,Inputs!$D$16:$I$16,Inputs!$D$24:$I$24) -> 37712 | H37: =SUM(D37:G37) -> 9464838 | I37: =IF(D37=0,0,F37/D37) -> 0.10224075
B38: 940360 | C38: Other wooden furniture | D38: =Inputs!$D$8*SUMPRODUCT(Scenarios!$D$30:$I$30,Inputs!$D$16:$I$16) -> 7000000 | E38: =Inputs!$D$8*SUMPRODUCT(Scenarios!$D$30:$I$30,Inputs!$D$16:$I$16,Inputs!$D$17:$I$17) -> 535150 | F38: =Inputs!$D$8*SUMPRODUCT(Scenarios!$D$30:$I$30,Inputs!$D$16:$I$16,Inputs!$D$39:$I$39) -> 873394.67 | G38: =Inputs!$D$8*SUMPRODUCT(Scenarios!$D$30:$I$30,Inputs!$D$16:$I$16,Inputs!$D$24:$I$24) -> 32998 | H38: =SUM(D38:G38) -> 8441542.7 | I38: =IF(D38=0,0,F38/D38) -> 0.12477067
B39: 940340 | C39: Kitchen cabinets and vanities | D39: =Inputs!$D$9*SUMPRODUCT(Scenarios!$D$31:$I$31,Inputs!$D$16:$I$16) -> 5000000 | E39: =Inputs!$D$9*SUMPRODUCT(Scenarios!$D$31:$I$31,Inputs!$D$16:$I$16,Inputs!$D$17:$I$17) -> 382500 | F39: =Inputs!$D$9*SUMPRODUCT(Scenarios!$D$31:$I$31,Inputs!$D$16:$I$16,Inputs!$D$40:$I$40) -> 1167668.9 | G39: =Inputs!$D$9*SUMPRODUCT(Scenarios!$D$31:$I$31,Inputs!$D$16:$I$16,Inputs!$D$24:$I$24) -> 23570 | H39: =SUM(D39:G39) -> 6573738.9 | I39: =IF(D39=0,0,F39/D39) -> 0.23353379
B40: 940171 | C40: Upholstered metal-frame seating | D40: =Inputs!$D$10*SUMPRODUCT(Scenarios!$D$32:$I$32,Inputs!$D$16:$I$16) -> 4000000 | E40: =Inputs!$D$10*SUMPRODUCT(Scenarios!$D$32:$I$32,Inputs!$D$16:$I$16,Inputs!$D$17:$I$17) -> 307800 | F40: =Inputs!$D$10*SUMPRODUCT(Scenarios!$D$32:$I$32,Inputs!$D$16:$I$16,Inputs!$D$41:$I$41) -> 391722.89 | G40: =Inputs!$D$10*SUMPRODUCT(Scenarios!$D$32:$I$32,Inputs!$D$16:$I$16,Inputs!$D$24:$I$24) -> 18856 | H40: =SUM(D40:G40) -> 4718378.9 | I40: =IF(D40=0,0,F40/D40) -> 0.097930723
B41: 940320 | C41: Other metal furniture | D41: =Inputs!$D$11*SUMPRODUCT(Scenarios!$D$33:$I$33,Inputs!$D$16:$I$16) -> 4000000 | E41: =Inputs!$D$11*SUMPRODUCT(Scenarios!$D$33:$I$33,Inputs!$D$16:$I$16,Inputs!$D$17:$I$17) -> 300400 | F41: =Inputs!$D$11*SUMPRODUCT(Scenarios!$D$33:$I$33,Inputs!$D$16:$I$16,Inputs!$D$42:$I$42) -> 419682.86 | G41: =Inputs!$D$11*SUMPRODUCT(Scenarios!$D$33:$I$33,Inputs!$D$16:$I$16,Inputs!$D$24:$I$24) -> 17913.2 | H41: =SUM(D41:G41) -> 4737996.1 | I41: =IF(D41=0,0,F41/D41) -> 0.10492071
C42: Total | D42: =SUM(D36:D41) -> 40000000 | E42: =SUM(E36:E41) -> 3054250 | F42: =SUM(F36:F41) -> 6620691.5 | G42: =SUM(G36:G41) -> 187617.2 | H42: =SUM(H36:H41) -> 49862559 | I42: =IF(D42=0,0,F42/D42) -> 0.16551729
B44: Scenario 4 | C44: =Scenarios!C37 -> Nearshore China volume to Mexico
B45: HS6 | C45: Product line | D45: FOB cost ($) | E45: Freight ($) | F45: Duty ($) | G45: Fees ($) | H45: Landed cost ($) | I45: Duty rate
B46: 940161 | C46: Upholstered wood-frame seating | D46: =Inputs!$D$6*SUMPRODUCT(Scenarios!$D$39:$I$39,Inputs!$D$16:$I$16) -> 12000000 | E46: =Inputs!$D$6*SUMPRODUCT(Scenarios!$D$39:$I$39,Inputs!$D$16:$I$16,Inputs!$D$17:$I$17) -> 687000 | F46: =Inputs!$D$6*SUMPRODUCT(Scenarios!$D$39:$I$39,Inputs!$D$16:$I$16,Inputs!$D$37:$I$37) -> 2955068.3 | G46: =Inputs!$D$6*SUMPRODUCT(Scenarios!$D$39:$I$39,Inputs!$D$16:$I$16,Inputs!$D$24:$I$24) -> 31112.4 | H46: =SUM(D46:G46) -> 15673181 | I46: =IF(D46=0,0,F46/D46) -> 0.24625569
B47: 940350 | C47: Wooden bedroom furniture | D47: =Inputs!$D$7*SUMPRODUCT(Scenarios!$D$40:$I$40,Inputs!$D$16:$I$16) -> 8000000 | E47: =Inputs!$D$7*SUMPRODUCT(Scenarios!$D$40:$I$40,Inputs!$D$16:$I$16,Inputs!$D$17:$I$17) -> 506000 | F47: =Inputs!$D$7*SUMPRODUCT(Scenarios!$D$40:$I$40,Inputs!$D$16:$I$16,Inputs!$D$38:$I$38) -> 580278.48 | G47: =Inputs!$D$7*SUMPRODUCT(Scenarios!$D$40:$I$40,Inputs!$D$16:$I$16,Inputs!$D$24:$I$24) -> 26398.4 | H47: =SUM(D47:G47) -> 9112676.9 | I47: =IF(D47=0,0,F47/D47) -> 0.07253481
...

Sheet Break-even
B1: How much more can a new factory charge?
B2: The highest price premium over China at which each origin is still cheaper landed (duty, freight and fees included). Negative = more expensive than China even at the same factory price.
B4: HS6 | C4: Product line | D4: Vietnam | E4: Malaysia | F4: Indonesia | G4: Cambodia | H4: Mexico
B5: 940161 | C5: Upholstered wood-frame seating | D5: =(1+Inputs!$D$17+Inputs!$D$37+Inputs!$D$24)/(1+Inputs!E$17+Inputs!E$37+Inputs!E$24)-1 -> 0.10566366 | E5: =(1+Inputs!$D$17+Inputs!$D$37+Inputs!$D$24)/(1+Inputs!F$17+Inputs!F$37+Inputs!F$24)-1 -> 0.10091283 | F5: =(1+Inputs!$D$17+Inputs!$D$37+Inputs!$D$24)/(1+Inputs!G$17+Inputs!G$37+Inputs!G$24)-1 -> 0.11605548 | G5: =(1+Inputs!$D$17+Inputs!$D$37+Inputs!$D$24)/(1+Inputs!H$17+Inputs!H$37+Inputs!H$24)-1 -> 0.098560332 | H5: =(1+Inputs!$D$17+Inputs!$D$37+Inputs!$D$24)/(1+Inputs!I$17+Inputs!I$37+Inputs!I$24)-1 -> 0.1471022
B6: 940350 | C6: Wooden bedroom furniture | D6: =(1+Inputs!$D$17+Inputs!$D$38+Inputs!$D$24)/(1+Inputs!E$17+Inputs!E$38+Inputs!E$24)-1 -> 0.20610626 | E6: =(1+Inputs!$D$17+Inputs!$D$38+Inputs!$D$24)/(1+Inputs!F$17+Inputs!F$38+Inputs!F$24)-1 -> 0.21676586 | F6: =(1+Inputs!$D$17+Inputs!$D$38+Inputs!$D$24)/(1+Inputs!G$17+Inputs!G$38+Inputs!G$24)-1 -> 0.20959892 | G6: =(1+Inputs!$D$17+Inputs!$D$38+Inputs!$D$24)/(1+Inputs!H$17+Inputs!H$38+Inputs!H$24)-1 -> 0.214597 | H6: =(1+Inputs!$D$17+Inputs!$D$38+Inputs!$D$24)/(1+Inputs!I$17+Inputs!I$38+Inputs!I$24)-1 -> 0.38117101
B7: 940360 | C7: Other wooden furniture | D7: =(1+Inputs!$D$17+Inputs!$D$39+Inputs!$D$24)/(1+Inputs!E$17+Inputs!E$39+Inputs!E$24)-1 -> 0.18124628 | E7: =(1+Inputs!$D$17+Inputs!$D$39+Inputs!$D$24)/(1+Inputs!F$17+Inputs!F$39+Inputs!F$24)-1 -> 0.21092772 | F7: =(1+Inputs!$D$17+Inputs!$D$39+Inputs!$D$24)/(1+Inputs!G$17+Inputs!G$39+Inputs!G$24)-1 -> 0.20857038 | G7: =(1+Inputs!$D$17+Inputs!$D$39+Inputs!$D$24)/(1+Inputs!H$17+Inputs!H$39+Inputs!H$24)-1 -> 0.17494683 | H7: =(1+Inputs!$D$17+Inputs!$D$39+Inputs!$D$24)/(1+Inputs!I$17+Inputs!I$39+Inputs!I$24)-1 -> 0.27560297
B8: 940340 | C8: Kitchen cabinets and vanities | D8: =(1+Inputs!$D$17+Inputs!$D$40+Inputs!$D$24)/(1+Inputs!E$17+Inputs!E$40+Inputs!E$24)-1 -> 0.11101839 | E8: =(1+Inputs!$D$17+Inputs!$D$40+Inputs!$D$24)/(1+Inputs!F$17+Inputs!F$40+Inputs!F$24)-1 -> 0.10279915 | F8: =(1+Inputs!$D$17+Inputs!$D$40+Inputs!$D$24)/(1+Inputs!G$17+Inputs!G$40+Inputs!G$24)-1 -> 0.10091672 | G8: =(1+Inputs!$D$17+Inputs!$D$40+Inputs!$D$24)/(1+Inputs!H$17+Inputs!H$40+Inputs!H$24)-1 -> 0.091246344 | H8: =(1+Inputs!$D$17+Inputs!$D$40+Inputs!$D$24)/(1+Inputs!I$17+Inputs!I$40+Inputs!I$24)-1 -> 0.15604912
B9: 940171 | C9: Upholstered metal-frame seating | D9: =(1+Inputs!$D$17+Inputs!$D$41+Inputs!$D$24)/(1+Inputs!E$17+Inputs!E$41+Inputs!E$24)-1 -> 0.075282239 | E9: =(1+Inputs!$D$17+Inputs!$D$41+Inputs!$D$24)/(1+Inputs!F$17+Inputs!F$41+Inputs!F$24)-1 -> 0.045543581 | F9: =(1+Inputs!$D$17+Inputs!$D$41+Inputs!$D$24)/(1+Inputs!G$17+Inputs!G$41+Inputs!G$24)-1 -> 0.080251167 | G9: =(1+Inputs!$D$17+Inputs!$D$41+Inputs!$D$24)/(1+Inputs!H$17+Inputs!H$41+Inputs!H$24)-1 -> 0.081696481 | H9: =(1+Inputs!$D$17+Inputs!$D$41+Inputs!$D$24)/(1+Inputs!I$17+Inputs!I$41+Inputs!I$24)-1 -> 0.22290954
B10: 940320 | C10: Other metal furniture | D10: =(1+Inputs!$D$17+Inputs!$D$42+Inputs!$D$24)/(1+Inputs!E$17+Inputs!E$42+Inputs!E$24)-1 -> 0.20566242 | E10: =(1+Inputs!$D$17+Inputs!$D$42+Inputs!$D$24)/(1+Inputs!F$17+Inputs!F$42+Inputs!F$24)-1 -> 0.21476158 | F10: =(1+Inputs!$D$17+Inputs!$D$42+Inputs!$D$24)/(1+Inputs!G$17+Inputs!G$42+Inputs!G$24)-1 -> 0.21988073 | G10: =(1+Inputs!$D$17+Inputs!$D$42+Inputs!$D$24)/(1+Inputs!H$17+Inputs!H$42+Inputs!H$24)-1 -> 0.21569441 | H10: =(1+Inputs!$D$17+Inputs!$D$42+Inputs!$D$24)/(1+Inputs!I$17+Inputs!I$42+Inputs!I$24)-1 -> 0.3328241
C12: Example: 20% in the Vietnam column means a Vietnamese factory can quote up to 20% above the China price for the same goods and still come out cheaper once the goods reach the US.

Sheet Duty rates
B1: Observed effective duty rates
B2: Source: US Census Bureau international trade API, imports for consumption. Rate = calculated duty / customs value.
B4: Effective duty rate, Jun-Aug 2026 (used by the model)
B5: HS6 | C5: Product line | D5: China | E5: Vietnam | F5: Malaysia | G5: Indonesia | H5: Cambodia | I5: Mexico
B6: 940161 | C6: Upholstered wood-frame seating | D6: 0.39330567 | E6: 0.24801316 | F6: 0.25374277 | G6: 0.23065041 | H6: 0.25159829 | I6: 0.24476363
B7: 940350 | C7: Wooden bedroom furniture | D7: 0.35496596 | E7: 0.10565416 | F7: 0.095269622 | G7: 0.097231466 | H7: 0.092367752 | I7: 0.00012161558
B8: 940360 | C8: Other wooden furniture | D8: 0.35788779 | E8: 0.1330744 | F8: 0.10334735 | G8: 0.10065494 | H8: 0.13457674 | I8: 0.088078125
B9: 940340 | C9: Kitchen cabinets and vanities | D9: 0.37895995 | E9: 0.22870174 | F9: 0.23845345 | G9: 0.23570735 | H9: 0.24740863 | I9: 0.22244998
B10: 940171 | C10: Upholstered metal-frame seating | D10: 0.19629297 | E10: 0.10230773 | F10: 0.13592827 | G10: 0.091870682 | H10: 0.090298581 | I10: 0.0043303298
B11: 940320 | C11: Other metal furniture | D11: 0.36629034 | E11: 0.11548319 | F11: 0.10653058 | G11: 0.096552585 | H11: 0.10062035 | I11: 0.046166177
B13: Effective duty rate, calendar 2024 (before the 2025 tariffs)
B14: HS6 | C14: Product line | D14: China | E14: Vietnam | F14: Malaysia | G14: Indonesia | H14: Cambodia | I14: Mexico
B15: 940161 | C15: Upholstered wood-frame seating | D15: 0.18586252 | E15: 0 | F15: 0 | G15: 0 | H15: 0 | I15: 0
B16: 940350 | C16: Wooden bedroom furniture | D16: 0.2495139 | E16: 0 | F16: 0 | G16: 0 | H16: 0 | I16: 0
B17: 940360 | C17: Other wooden furniture | D17: 0.24004048 | E17: 0 | F17: 0 | G17: 0 | H17: 0 | I17: 0
B18: 940340 | C18: Kitchen cabinets and vanities | D18: 0.24465615 | E18: 0 | F18: 0 | G18: 0 | H18: 0 | I18: 0
B19: 940171 | C19: Upholstered metal-frame seating | D19: 0.14318913 | E19: 0 | F19: 0 | G19: 0 | H19: 0 | I19: 0
B20: 940320 | C20: Other metal furniture | D20: 0.20970797 | E20: 0 | F20: 0 | G20: 0 | H20: 0 | I20: 0
B22: Change since 2024 (percentage points)
B23: HS6 | C23: Product line | D23: China | E23: Vietnam | F23: Malaysia | G23: Indonesia | H23: Cambodia | I23: Mexico
B24: 940161 | C24: Upholstered wood-frame seating | D24: =(D6-D15)*100 -> 20.744314 | E24: =(E6-E15)*100 -> 24.801316 | F24: =(F6-F15)*100 -> 25.374277 | G24: =(G6-G15)*100 -> 23.065041 | H24: =(H6-H15)*100 -> 25.159829 | I24: =(I6-I15)*100 -> 24.476363
B25: 940350 | C25: Wooden bedroom furniture | D25: =(D7-D16)*100 -> 10.545206 | E25: =(E7-E16)*100 -> 10.565416 | F25: =(F7-F16)*100 -> 9.5269622 | G25: =(G7-G16)*100 -> 9.7231466 | H25: =(H7-H16)*100 -> 9.2367752 | I25: =(I7-I16)*100 -> 0.012161558
B26: 940360 | C26: Other wooden furniture | D26: =(D8-D17)*100 -> 11.784731 | E26: =(E8-E17)*100 -> 13.30744 | F26: =(F8-F17)*100 -> 10.334735 | G26: =(G8-G17)*100 -> 10.065494 | H26: =(H8-H17)*100 -> 13.457674 | I26: =(I8-I17)*100 -> 8.8078125
B27: 940340 | C27: Kitchen cabinets and vanities | D27: =(D9-D18)*100 -> 13.430379 | E27: =(E9-E18)*100 -> 22.870174 | F27: =(F9-F18)*100 -> 23.845345 | G27: =(G9-G18)*100 -> 23.570735 | H27: =(H9-H18)*100 -> 24.740863 | I27: =(I9-I18)*100 -> 22.244998
B28: 940171 | C28: Upholstered metal-frame seating | D28: =(D10-D19)*100 -> 5.3103844 | E28: =(E10-E19)*100 -> 10.230773 | F28: =(F10-F19)*100 -> 13.592827 | G28: =(G10-G19)*100 -> 9.1870682 | H28: =(H10-H19)*100 -> 9.0298581 | I28: =(I10-I19)*100 -> 0.43303298
B29: 940320 | C29: Other metal furniture | D29: =(D11-D20)*100 -> 15.658237 | E29: =(E11-E20)*100 -> 11.548319 | F29: =(F11-F20)*100 -> 10.653058 | G29: =(G11-G20)*100 -> 9.6552585 | H29: =(H11-H20)*100 -> 10.062035 | I29: =(I11-I20)*100 -> 4.6166177
B31: Goods value behind each rate above, Jun-Aug 2026 ($)
B32: HS6 | C32: Product line | D32: China | E32: Vietnam | F32: Malaysia | G32: Indonesia | H32: Cambodia | I32: Mexico
B33: 940161 | C33: Upholstered wood-frame seating | D33: 109407053 | E33: 798804423 | F33: 24488276 | G33: 13327676 | H33: 72674132 | I33: 100123475
B34: 940350 | C34: Wooden bedroom furniture | D34: 14486296 | E34: 399718749 | F34: 59569083 | G34: 36731895 | H34: 6868068 | I34: 18829825
B35: 940360 | C35: Other wooden furniture | D35: 151936897 | E35: 501823846 | F35: 57538358 | G35: 71221829 | H35: 9027214 | I35: 50123070
B36: 940340 | C36: Kitchen cabinets and vanities | D36: 5739662 | E36: 184492889 | F36: 28164101 | G36: 9242478 | H36: 24026923 | I36: 29039589
B37: 940171 | C37: Upholstered metal-frame seating | D37: 180496964 | E37: 40098895 | F37: 1976041 | G37: 2977642 | H37: 7087520 | I37: 40501996
B38: 940320 | C38: Other metal furniture | D38: 369701179 | E38: 183115128 | F38: 5628459 | G38: 7274378 | H38: 59967524 | I38: 107747346
B40: Rates fell back to the origin's all-line rate for: Malaysia / Upholstered metal-frame seating
